Workbook

Sheet Hoja1
A1: Fecha | B1: Rubro | C1: Unidad de producción | D1: Cosecha/Tarea | E1: Producción/Quintales | F1: Productividad (QQ/TAS) | G1: Productividad (kg/TAS) | H1: Precio | I1: Unidad de precio | J1: Precio por kg | K1: Costos
A2: 36526 | B2: Arroz | C2: Quintal | D2: 67860 | E2: 170243 | F2: =E2/D2 -> 2.5087386 | G2: =F2*45.36 -> 113.79638 | H2: 1066.8669 | I2: Fan. 110 Kg | J2: =H2/110 -> 9.6987899
A3: 36557 | B3: Arroz | C3: Quintal | D3: 15498 | E3: 35642 | F3: =E3/D3 -> 2.2997806 | G3: =F3*45.36 -> 104.31805 | H3: 956.45545 | I3: Fan. 110 Kg | J3: =H3/110 -> 8.6950495
A4: 36586 | B4: Arroz | C4: Quintal | D4: 7902 | E4: 23368 | F4: =E4/D4 -> 2.957226 | G4: =F4*45.36 -> 134.13977 | H4: 1156.077 | I4: Fan. 110 Kg | J4: =H4/110 -> 10.509791
A5: 36617 | B5: Arroz | C5: Quintal | D5: 37236 | E5: 139693 | F5: =E5/D5 -> 3.7515576 | G5: =F5*45.36 -> 170.17065 | H5: 1093.4895 | I5: Fan. 110 Kg | J5: =H5/110 -> 9.9408141
A6: 36647 | B6: Arroz | C6: Quintal | D6: 222362 | E6: 1031097 | F6: =E6/D6 -> 4.6370198 | G6: =F6*45.36 -> 210.33522 | H6: 1163.5314 | I6: Fan. 110 Kg | J6: =H6/110 -> 10.577558
A7: 36678 | B7: Arroz | C7: Quintal | D7: 340330 | E7: 1745864 | F7: =E7/D7 -> 5.1299151 | G7: =F7*45.36 -> 232.69295 | H7: 1022.7943 | I7: Fan. 110 Kg | J7: =H7/110 -> 9.2981298
A8: 36708 | B8: Arroz | C8: Quintal | D8: 197810 | E8: 1051585 | F8: =E8/D8 -> 5.3161367 | G8: =F8*45.36 -> 241.13996 | H8: 1087.802 | I8: Fan. 110 Kg | J8: =H8/110 -> 9.8891089
A9: 36739 | B9: Arroz | C9: Quintal | D9: 126214 | E9: 612099 | F9: =E9/D9 -> 4.8496918 | G9: =F9*45.36 -> 219.98202 | H9: 980.80308 | I9: Fan. 110 Kg | J9: =H9/110 -> 8.9163916
A10: 36770 | B10: Arroz | C10: Quintal | D10: 191615 | E10: 750970 | F10: =E10/D10 -> 3.9191608 | G10: =F10*45.36 -> 177.77313 | H10: 1007.2321 | I10: Fan. 110 Kg | J10: =H10/110 -> 9.1566557
A11: 36800 | B11: Arroz | C11: Quintal | D11: 322266 | E11: 1171356 | F11: =E11/D11 -> 3.6347489 | G11: =F11*45.36 -> 164.87221 | H11: 944.81408 | I11: Fan. 110 Kg | J11: =H11/110 -> 8.5892189
A12: 36831 | B12: Arroz | C12: Quintal | D12: 300096 | E12: 1038734 | F12: =E12/D12 -> 3.461339 | G12: =F12*45.36 -> 157.00634 | H12: 996.65567 | I12: Fan. 110 Kg | J12: =H12/110 -> 9.0605061
A13: 36861 | B13: Arroz | C13: Quintal | D13: 164365 | E13: 546838 | F13: =E13/D13 -> 3.3269735 | G13: =F13*45.36 -> 150.91152 | H13: 1068.8515 | I13: Fan. 110 Kg | J13: =H13/110 -> 9.7168317
A14: 36526 | B14: Maíz | C14: Quintal | D14: 28486 | E14: 47296 | F14: =E14/D14 -> 1.6603244 | G14: =F14*45.36 -> 75.312313 | H14: 102.7445 | I14: Quintal | J14: =H14/45.36 -> 2.2650904
A15: 36557 | B15: Maíz | C15: Quintal | D15: 32095 | E15: 59991 | F15: =E15/D15 -> 1.8691697 | G15: =F15*45.36 -> 84.785535 | H15: 117.713 | I15: Quintal | J15: =H15/45.36 -> 2.5950838
A16: 36586 | B16: Maíz | C16: Quintal | D16: 16370 | E16: 28986 | F16: =E16/D16 -> 1.7706781 | G16: =F16*45.36 -> 80.317957 | H16: 124.8009 | I16: Quintal | J16: =H16/45.36 -> 2.7513426
A17: 36617 | B17: Maíz | C17: Quintal | D17: 21666 | E17: 40527 | F17: =E17/D17 -> 1.8705345 | G17: =F17*45.36 -> 84.847444 | H17: 155.20686 | I17: Quintal | J17: =H17/45.36 -> 3.4216679
A18: 36647 | B18: Maíz | C18: Quintal | D18: 15499 | E18: 30310 | F18: =E18/D18 -> 1.95561 | G18: =F18*45.36 -> 88.706471 | H18: 161.376 | I18: Quintal | J18: =H18/45.36 -> 3.557672
A19: 36678 | B19: Maíz | C19: Quintal | D19: 20946 | E19: 35647 | F19: =E19/D19 -> 1.7018524 | G19: =F19*45.36 -> 77.196024 | H19: 143.10516 | I19: Quintal | J19: =H19/45.36 -> 3.1548757
A20: 36708 | B20: Maíz | C20: Quintal | D20: 20492 | E20: 33257 | F20: =E20/D20 -> 1.622926 | G20: =F20*45.36 -> 73.615924 | H20: 120.24 | I20: Quintal | J20: =H20/45.36 -> 2.6507937
A21: 36739 | B21: Maíz | C21: Quintal | D21: 34200 | E21: 57065 | F21: =E21/D21 -> 1.6685673 | G21: =F21*45.36 -> 75.686211 | H21: 114.8976 | I21: Quintal | J21: =H21/45.36 -> 2.5330159
A22: 36770 | B22: Maíz | C22: Quintal | D22: 24151 | E22: 39667 | F22: =E22/D22 -> 1.6424579 | G22: =F22*45.36 -> 74.501889 | H22: 130.06775 | I22: Quintal | J22: =H22/45.36 -> 2.8674548
A23: 36800 | B23: Maíz | C23: Quintal | D23: 29711 | E23: 50863 | F23: =E23/D23 -> 1.7119249 | G23: =F23*45.36 -> 77.652912 | H23: 107.064 | I23: Quintal | J23: =H23/45.36 -> 2.3603175
A24: 36831 | B24: Maíz | C24: Quintal | D24: 36728 | E24: 63486 | F24: =E24/D24 -> 1.728545 | G24: =F24*45.36 -> 78.4068 | H24: 118.041 | I24: Quintal | J24: =H24/45.36 -> 2.6023148
A25: 36861 | B25: Maíz | C25: Quintal | D25: 27775 | E25: 40210 | F25: =E25/D25 -> 1.4477048 | G25: =F25*45.36 -> 65.667888 | H25: 127.90208 | I25: Quintal | J25: =H25/45.36 -> 2.8197108
... A109: 36861 | B109: Berenjena | C109: Quintal | D109: 2277 | E109: 18817 | F109: =E109/D109 -> 8.2639438 | G109: =F109*45.36 -> 374.85249 | H109: 148.16667 | I109: Quintal | J109: =H109/45.36 -> 3.2664609
A110: 36526 | B110: Aguacate | C110: Quintal | D110: 6878 | E110: 7434 | F110: =E110/D110 -> 1.0808375 | G110: =F110*45.36 -> 49.026787 | H110: 1262.5 | I110: Millar | J110: =(H110/1000)/0.56234 -> 2.245083
A111: 36557 | B111: Aguacate | C111: Quintal | D111: 1157 | E111: 1610 | F111: =E111/D111 -> 1.3915298 | G111: =F111*45.36 -> 63.119793 | H111: 1840 | I111: Millar | J111: =(H111/1000)/0.56234 -> 3.2720418
A112: 36586 | B112: Aguacate | C112: Quintal | D112: 356 | E112: 367 | F112: =E112/D112 -> 1.0308989 | G112: =F112*45.36 -> 46.761573 | H112: 1917.38 | I112: Millar | J112: =(H112/1000)/0.56234 -> 3.4096454
A113: 36617 | B113: Aguacate | C113: Quintal | D113: 113 | E113: 36 | F113: =E113/D113 -> 0.31858407 | G113: =F113*45.36 -> 14.450973 | H113: 1325 | I113: Millar | J113: =(H113/1000)/0.56234 -> 2.3562258
A114: 36647 | B114: Aguacate | C114: Quintal | D114: 79 | E114: 46 | F114: =E114/D114 -> 0.58227848 | G114: =F114*45.36 -> 26.412152 | H114: 1924.1 | I114: Millar | J114: =(H114/1000)/0.56234 -> 3.4215955
A115: 36678 | B115: Aguacate | C115: Quintal | D115: 70 | E115: 112 | F115: =E115/D115 -> 1.6 | G115: =F115*45.36 -> 72.576 | H115: 1716.5 | I115: Millar | J115: =(H115/1000)/0.56234 -> 3.0524238
A116: 36708 | B116: Aguacate | C116: Quintal | D116: 5988 | E116: 5178 | F116: =E116/D116 -> 0.86472946 | G116: =F116*45.36 -> 39.224128 | H116: 953.39 | I116: Millar | J116: =(H116/1000)/0.56234 -> 1.6953978
A117: 36739 | B117: Aguacate | C117: Quintal | D117: 12066 | E117: 22422 | F117: =E117/D117 -> 1.8582795 | G117: =F117*45.36 -> 84.291556 | H117: 954.13 | I117: Millar | J117: =(H117/1000)/0.56234 -> 1.6967137
A118: 36770 | B118: Aguacate | C118: Quintal | D118: 21733 | E118: 45092 | F118: =E118/D118 -> 2.0748171 | G118: =F118*45.36 -> 94.113704 | H118: 927.18 | I118: Millar | J118: =(H118/1000)/0.56234 -> 1.648789
A119: 36800 | B119: Aguacate | C119: Quintal | D119: 18849 | E119: 34864 | F119: =E119/D119 -> 1.8496472 | G119: =F119*45.36 -> 83.899997 | H119: 943.334 | I119: Millar | J119: =(H119/1000)/0.56234 -> 1.6775154
A120: 36831 | B120: Aguacate | C120: Quintal | D120: 14085 | E120: 25207 | F120: =E120/D120 -> 1.7896344 | G120: =F120*45.36 -> 81.177815 | H120: 1960 | I120: Millar | J120: =(H120/1000)/0.56234 -> 3.4854359
A121: 36861 | B121: Aguacate | C121: Quintal | D121: 15627 | E121: 37827 | F121: =E121/D121 -> 2.4206182 | G121: =F121*45.36 -> 109.79924 | H121: 2662.5 | I121: Millar | J121: =(H121/1000)/0.56234 -> 4.7346801
A122: 36526 | B122: Guineo | C122: Racimo | D122: 213160 | E122: 1394241 | F122: =E122/D122 -> 6.5408191 | G122: =F122*27.21 -> 177.97569 | H122: 18.625 | I122: Racimo/60 Lb/120Ud. | J122: =H122/27.21 -> 0.684491
A123: 36557 | B123: Guineo | C123: Racimo | D123: 212414 | E123: 1123980 | F123: =E123/D123 -> 5.2914591 | G123: =F123*27.21 -> 143.9806 | H123: 21.46125 | I123: Racimo/60 Lb/120Ud. | J123: =H123/27.21 -> 0.78872657
...

Sheet Hoja3
A1: ** | B1: en racimos
A2: * | B2: millares
A5: En QQ a partir de 2015
A6: Guineo
A7: Plátano
A13: Peso promedio plátano (lb) | B13: 0.9
A14: Peso promedio guineo (lb) | B14: 0.5
A15: Peso promedio plátano (kg) | B15: =B13*B20 -> 0.40815 | D15: =B15*1000 -> 408.15
A17: Peso promedio guineo (kg) | B17: =B14*B20 -> 0.22675
A18: Peso promedio del racimo de plátano (Supuesto) | B18: 40 | C18: kg | D18: 30-50 kg
A20: 1 lb | B20: 0.4535 | C20: kg
B21: 45.36
A23: Racimo de guineo (lb) | B23: 60
A24: Racimo de guineo (kg) | B24: =B23*B20 -> 27.21
A27: Peso promedio del aguacate(lb) | B27: 1.24
A28: Peso promedio del aguacate(kg) | B28: =B27*B20 -> 0.56234 | D28: =1000*B28 -> 562.34
A33: Precio
A34: Arroz Cáscara | B34: Fan. 110 kg | C34: Se divide entre 110
A35: Maíz | B35: Quintal | C35: Se divide por 45.36
A36: Batata | B36: Quintal | C36: Se divide por 45.37
A37: Ñame | B37: Quintal | C37: Se divide por 45.38
A38: Papa blanca | B38: Quintal | C38: Se divide por 45.39
A39: Yautía | B39: Quintal | C39: Se divide por 45.40
A40: Yuca | B40: Quintal | C40: Se divide por 45.41 | D40: Dulce
A41: Auyama | B41: Quintal | C41: Se divide por 45.42
A42: Berenjena | B42: Quintal | C42: Se divide por 45.43
A43: Aguacate | B43: Millar | C43: 1000 y luego 0.56234
A44: Guineo | B44: Racimo | C44: se divide entre 27.21
A45: Plátano | B45: Millar | C45: 1000 y luego 0.40815

Sheet Hoja2
